DNotesRuntimeException: exception in method test4()
	at ExceptionTest.doTest4(ExceptionTest.java:62)
	at ExceptionTest.doTest3(ExceptionTest.java:55)
	at ExceptionTest.doTest2(ExceptionTest.java:51)
	at ExceptionTest.doTest1(ExceptionTest.java:47)
	at ExceptionTest.testException(ExceptionTest.java:40)
	at sun.reflect.NativeMethodAccessorImpl.invoke0(Native Method)
	at sun.reflect.NativeMethodAccessorImpl.invoke(NativeMethodAccessorImpl.java:39)
	at sun.reflect.DelegatingMethodAccessorImpl.invoke(DelegatingMethodAccessorImpl.java:25)
	at java.lang.reflect.Method.invoke(Method.java:324)
	at junit.framework.TestCase.runTest(TestCase.java:154)
	at junit.framework.TestCase.runBare(TestCase.java:127)
	at junit.framework.TestResult$1.protect(TestResult.java:106)
	at junit.framework.TestResult.runProtected(TestResult.java:124)
	at junit.framework.TestResult.run(TestResult.java:109)
	at junit.framework.TestCase.run(TestCase.java:118)
	at junit.framework.TestSuite.runTest(TestSuite.java:208)
	at junit.framework.TestSuite.run(TestSuite.java:203)
	at org.eclipse.jdt.internal.junit.runner.junit3.JUnit3TestReference.run(JUnit3TestReference.java:128)
	at org.eclipse.jdt.internal.junit.runner.TestExecution.run(TestExecution.java:38)
	at org.eclipse.jdt.internal.junit.runner.RemoteTestRunner.runTests(RemoteTestRunner.java:460)
	at org.eclipse.jdt.internal.junit.runner.RemoteTestRunner.runTests(RemoteTestRunner.java:673)
	at org.eclipse.jdt.internal.junit.runner.RemoteTestRunner.run(RemoteTestRunner.java:386)
	at org.eclipse.jdt.internal.junit.runner.RemoteTestRunner.main(RemoteTestRunner.java:196)
Caused by: DNotesRuntimeException: exception in method test8()
	at ExceptionTest.doTest8(ExceptionTest.java:79)
	at ExceptionTest.doTest7(ExceptionTest.java:75)
	at ExceptionTest.doTest6(ExceptionTest.java:71)
	at ExceptionTest.doTest5(ExceptionTest.java:67)
	at ExceptionTest.doTest4(ExceptionTest.java:60)
	... 22 more
